<?xml version="1.0" encoding="utf-8"?>
<!-- This URDF was automatically created by SolidWorks to URDF Exporter! Originally created by Stephen Brawner (brawner@gmail.com) 
     Commit Version: 1.6.0-4-g7f85cfe  Build Version: 1.6.7995.38578
     For more information, please see http://wiki.ros.org/sw_urdf_exporter -->
<robot
  name="Assem1">
  <link
    name="base_link">
    <inertial>
      <origin
        xyz="0.0205389141568959 0.13066120273112 2.51498855319307E-11"
        rpy="0 0 0" />
      <mass
        value="10.3245748603134" />
      <inertia
        ixx="0.144071352653831"
        ixy="1.1707235989081E-09"
        ixz="9.50016320595649E-10"
        iyy="0.983008887820795"
        iyz="6.98412626725908E-10"
        izz="0.862088865572747" />
    </inertial>
    <visual>
      <origin
        xyz="0 0 0"
        rpy="0 0 0" />
      <geometry>
        <mesh
          filename="package://Assem1/meshes/base_link.STL" />
      </geometry>
      <material
        name="">
        <color
          rgba="0.898039215686275 0.917647058823529 0.929411764705882 1" />
      </material>
    </visual>
    <collision>
      <origin
        xyz="0 0 0"
        rpy="0 0 0" />
      <geometry>
        <mesh
          filename="package://Assem1/meshes/base_link.STL" />
      </geometry>
    </collision>
  </link>
  <link
    name="back_right_wheel">
    <inertial>
      <origin
        xyz="0.78175 -0.232155 -0.204995"
        rpy="0 0 0" />
      <mass
        value="3.14159265358979" />
      <inertia
        ixx="0.015707963267949"
        ixy="-6.22833660358683E-19"
        ixz="-4.2926491687472E-32"
        iyy="0.010471975511966"
        iyz="5.23622179005125E-48"
        izz="0.010471975511966" />
    </inertial>
    <visual>
      <origin
        xyz="0 0 0"
        rpy="0 0 0" />
      <geometry>
        <mesh
          filename="package://Assem1/meshes/back_right_wheel.STL" />
      </geometry>
      <material
        name="">
        <color
          rgba="0.792156862745098 0.819607843137255 0.933333333333333 1" />
      </material>
    </visual>
    <collision>
      <origin
        xyz="0 0 0"
        rpy="0 0 0" />
      <geometry>
        <mesh
          filename="package://Assem1/meshes/back_right_wheel.STL" />
      </geometry>
    </collision>
  </link>
  <joint
    name="back_right_joint"
    type="continuous">
    <origin
      xyz="0 0 0"
      rpy="0 0 0" />
    <parent
      link="base_link" />
    <child
      link="back_right_wheel" />
    <axis
      xyz="-1 0 0" />
  </joint>
  <link
    name="front_right_wheel">
    <inertial>
      <origin
        xyz="0.78175 0.232154999999999 -0.205"
        rpy="0 0 0" />
      <mass
        value="3.14159265358979" />
      <inertia
        ixx="0.015707963267949"
        ixy="-5.07934344092487E-19"
        ixz="5.33648472500243E-19"
        iyy="0.010471975511966"
        iyz="3.50106951531777E-19"
        izz="0.010471975511966" />
    </inertial>
    <visual>
      <origin
        xyz="0 0 0"
        rpy="0 0 0" />
      <geometry>
        <mesh
          filename="package://Assem1/meshes/front_right_wheel.STL" />
      </geometry>
      <material
        name="">
        <color
          rgba="0.792156862745098 0.819607843137255 0.933333333333333 1" />
      </material>
    </visual>
    <collision>
      <origin
        xyz="0 0 0"
        rpy="0 0 0" />
      <geometry>
        <mesh
          filename="package://Assem1/meshes/front_right_wheel.STL" />
      </geometry>
    </collision>
  </link>
  <joint
    name="front_right_joint"
    type="continuous">
    <origin
      xyz="0 0 0"
      rpy="0 0 0" />
    <parent
      link="base_link" />
    <child
      link="front_right_wheel" />
    <axis
      xyz="-1 0 0" />
  </joint>
  <link
    name="back_left_wheel">
    <inertial>
      <origin
        xyz="-0.78175 -0.232155 -0.204995"
        rpy="0 0 0" />
      <mass
        value="3.14159265358979" />
      <inertia
        ixx="0.015707963267949"
        ixy="-6.02837043411598E-19"
        ixz="4.3824477612266E-19"
        iyy="0.010471975511966"
        iyz="7.90564084104014E-19"
        izz="0.010471975511966" />
    </inertial>
    <visual>
      <origin
        xyz="0 0 0"
        rpy="0 0 0" />
      <geometry>
        <mesh
          filename="package://Assem1/meshes/back_left_wheel.STL" />
      </geometry>
      <material
        name="">
        <color
          rgba="0.792156862745098 0.819607843137255 0.933333333333333 1" />
      </material>
    </visual>
    <collision>
      <origin
        xyz="0 0 0"
        rpy="0 0 0" />
      <geometry>
        <mesh
          filename="package://Assem1/meshes/back_left_wheel.STL" />
      </geometry>
    </collision>
  </link>
  <joint
    name="back_right_joint"
    type="continuous">
    <origin
      xyz="0 0 0"
      rpy="0 0 0" />
    <parent
      link="base_link" />
    <child
      link="back_left_wheel" />
    <axis
      xyz="-1 0 0" />
  </joint>
  <link
    name="front_left_wheel">
    <inertial>
      <origin
        xyz="-0.78175 0.232155 -0.205"
        rpy="0 0 0" />
      <mass
        value="3.14159265358979" />
      <inertia
        ixx="0.015707963267949"
        ixy="-1.30733605176784E-18"
        ixz="-7.7085827248129E-19"
        iyy="0.010471975511966"
        iyz="9.260893556647E-19"
        izz="0.010471975511966" />
    </inertial>
    <visual>
      <origin
        xyz="0 0 0"
        rpy="0 0 0" />
      <geometry>
        <mesh
          filename="package://Assem1/meshes/front_left_wheel.STL" />
      </geometry>
      <material
        name="">
        <color
          rgba="0.792156862745098 0.819607843137255 0.933333333333333 1" />
      </material>
    </visual>
    <collision>
      <origin
        xyz="0 0 0"
        rpy="0 0 0" />
      <geometry>
        <mesh
          filename="package://Assem1/meshes/front_left_wheel.STL" />
      </geometry>
    </collision>
  </link>
  <joint
    name="front_left_joint"
    type="continuous">
    <origin
      xyz="0 0 0"
      rpy="0 0 0" />
    <parent
      link="base_link" />
    <child
      link="front_left_wheel" />
    <axis
      xyz="-1 0 0" />
  </joint>
</robot>