<?xml version="1.0" ?>
<!-- =================================================================================== -->
<!-- |    This document was autogenerated by xacro from robot2.xacro                   | -->
<!-- |    EDITING THIS FILE BY HAND IS NOT RECOMMENDED                                 | -->
<!-- =================================================================================== -->
<robot name="robot">
  <!-- Specify some standard inertial calculations https://en.wikipedia.org/wiki/List_of_moments_of_inertia -->
  <!-- These make use of xacro's mathematical functionality -->
  <ros2_control name="GazeboSystem" type="system">
    <hardware>
      <plugin>gazebo_ros2_control/GazeboSystem</plugin>
    </hardware>
    <joint name="left_joint_b">
      <command_interface name="velocity"/>
      <state_interface name="position">
        <param name="initial_value">0.0</param>
      </state_interface>
      <state_interface name="velocity"/>
      <state_interface name="effort"/>
    </joint>
    <joint name="right_joint_b">
      <command_interface name="velocity"/>
      <state_interface name="position">
        <param name="initial_value">0.0</param>
      </state_interface>
      <state_interface name="velocity"/>
      <state_interface name="effort"/>
    </joint>
    <joint name="left_joint_f">
      <command_interface name="velocity"/>
      <state_interface name="position">
        <param name="initial_value">0.0</param>
      </state_interface>
      <state_interface name="velocity"/>
      <state_interface name="effort"/>
    </joint>
    <joint name="right_joint_f">
      <command_interface name="velocity"/>
      <state_interface name="position">
        <param name="initial_value">0.0</param>
      </state_interface>
      <state_interface name="velocity"/>
      <state_interface name="effort"/>
    </joint>
  </ros2_control>
  <gazebo>
    <plugin filename="libgazebo_ros2_control.so" name="gazebo_ros2_control">
      <robot_sim_type>gazebo_ros2_control/GazeboSystem</robot_sim_type>
      <parameters>/home/ponwalai/project_ws/install/lidar_description/share/lidar_description/config/example_controllers.yaml</parameters>
    </plugin>
    <plugin filename="libgazebo_ros_p3d.so" name="ground_truth_plugin">
      <alwaysOn>true</alwaysOn>
      <updateRate>50.0</updateRate>
      <bodyName>base_link</bodyName>
      <topicName>ground_truth/state</topicName>
      <gaussianNoise>0.01</gaussianNoise>
      <frameName>world</frameName>
      <xyzOffsets>0 0 0</xyzOffsets>
      <rpyOffsets>0 0 0</rpyOffsets>
    </plugin>
  </gazebo>
  <gazebo reference="dummy">
    <gravity>true</gravity>
    <sensor name="lidar_sensor" type="ray">
      <pose>0.17 0 0.6 0 1.5707 0</pose>
      <visualize>true</visualize>
      <update_rate>10</update_rate>
      <ray>
        <scan>
          <horizontal>
            <sample>720</sample>
            <resolution>1.125</resolution>
            <min_angle>0</min_angle>
            <max_angle>6.28318530718 </max_angle>
          </horizontal>
        </scan>
        <range>
          <min>0.05</min>
          <max>16</max>
          <resolution>000001</resolution>
        </range>
      </ray>
      <plugin filename="libgazebo_ros_ray_sensor.so" name="lidar">
        <output_type>sensor_msgs/LaserScan</output_type>
      </plugin>
    </sensor>
    <sensor name="imu_sensor" type="imu">
      <pose>0.17 0 0.6 0 0 0</pose>
      <always_on>true</always_on>
      <update_rate>10</update_rate>
      <visualize>true</visualize>
      <topic>__default_topic__</topic>
      <plugin filename="libgazebo_ros_imu_sensor.so" name="imu">
        <topicName>imu</topicName>
        <bodyName>dummy</bodyName>
        <updateRateHZ>10.0</updateRateHZ>
        <gaussianNoise>0.0</gaussianNoise>
        <xyzOffset>0 0 0</xyzOffset>
        <rpyOffset>0 0 0</rpyOffset>
        <frameName>dummy</frameName>
        <initialOrientationAsReference>false</initialOrientationAsReference>
      </plugin>
    </sensor>
    <mu1>0.2</mu1>
    <mu2>0.2</mu2>
    <material>Gazebo/Green</material>
  </gazebo>
  <gazebo reference="base_link">
    <mu1>0.2</mu1>
    <mu2>0.2</mu2>
    <material>Gazebo/Green</material>
  </gazebo>
  <gazebo reference="left_wheel_f">
    <mu1>0.85</mu1>
    <mu2>0.65</mu2>
    <material>Gazebo/Red</material>
  </gazebo>
  <gazebo reference="left_wheel_b">
    <mu1>0.85</mu1>
    <mu2>0.65</mu2>
    <material>Gazebo/Red</material>
  </gazebo>
  <gazebo reference="right_wheel_f">
    <mu1>0.85</mu1>
    <mu2>0.65</mu2>
    <material>Gazebo/Blue</material>
  </gazebo>
  <gazebo reference="right_wheel_b">
    <mu1>0.85</mu1>
    <mu2>0.65</mu2>
    <material>Gazebo/Blue</material>
  </gazebo>
  <material name="white">
    <color rgba="1 1 1 1"/>
  </material>
  <link name="dummy"/>
  <joint name="dummy" type="fixed">
    <parent link="dummy"/>
    <child link="base_link"/>
    <origin rpy="0 0 0" xyz="0 0 0.305"/>
  </joint>
  <link name="base_link">
    <inertial>
      <origin rpy="0 0 0" xyz="0 0 0.15175 "/>
      <mass value="10.5"/>
      <inertia ixx="1.7955982187499995" ixy="0.0" ixz="0.0" iyy="0.9555982187500001" iyz="0.0" izz="2.59"/>
    </inertial>
    <visual>
      <origin rpy="0 0 0" xyz="0 0 0"/>
      <geometry>
        <mesh filename="file:////home/ponwalai/project_ws/install/lidar_description/share/lidar_description/meshes/base_link.STL"/>
      </geometry>
      <material name="white"/>
    </visual>
    <collision>
      <origin rpy="0 0 0" xyz="0 0 0"/>
      <geometry>
        <mesh filename="file:////home/ponwalai/project_ws/install/lidar_description/share/lidar_description/meshes/base_link.STL"/>
      </geometry>
    </collision>
  </link>
  <link name="right_wheel_b">
    <inertial>
      <origin rpy="0 0 0" xyz="0 0 0"/>
      <mass value="5.5"/>
      <inertia ixx="0.018333333333333337" ixy="0.0" ixz="0.0" iyy="0.018333333333333337" iyz="0.0" izz="0.027500000000000004"/>
    </inertial>
    <visual>
      <origin rpy="0 0 0" xyz="0 0 0"/>
      <geometry>
        <mesh filename="file:////home/ponwalai/project_ws/install/lidar_description/share/lidar_description/meshes/wheel.STL"/>
      </geometry>
      <material name="white"/>
    </visual>
    <collision>
      <origin rpy="0 0 0" xyz="0 0 0"/>
      <geometry>
        <mesh filename="file:////home/ponwalai/project_ws/install/lidar_description/share/lidar_description/meshes/wheel.STL"/>
      </geometry>
    </collision>
  </link>
  <link name="left_wheel_b">
    <inertial>
      <origin rpy="0 0 0" xyz="0 0 0"/>
      <mass value="5.5"/>
      <inertia ixx="0.018333333333333337" ixy="0.0" ixz="0.0" iyy="0.018333333333333337" iyz="0.0" izz="0.027500000000000004"/>
    </inertial>
    <visual>
      <origin rpy="0 0 0" xyz="0 0 0"/>
      <geometry>
        <mesh filename="file:////home/ponwalai/project_ws/install/lidar_description/share/lidar_description/meshes/wheel.STL"/>
      </geometry>
      <material name="white"/>
    </visual>
    <collision>
      <origin rpy="0 0 0" xyz="0 0 0"/>
      <geometry>
        <mesh filename="file:////home/ponwalai/project_ws/install/lidar_description/share/lidar_description/meshes/wheel.STL"/>
      </geometry>
    </collision>
  </link>
  <link name="right_wheel_f">
    <inertial>
      <origin rpy="0 0 0" xyz="0 0 0"/>
      <mass value="5.5"/>
      <inertia ixx="0.018333333333333337" ixy="0.0" ixz="0.0" iyy="0.018333333333333337" iyz="0.0" izz="0.027500000000000004"/>
    </inertial>
    <visual>
      <origin rpy="0 0 0" xyz="0 0 0"/>
      <geometry>
        <mesh filename="file:////home/ponwalai/project_ws/install/lidar_description/share/lidar_description/meshes/wheel.STL"/>
      </geometry>
      <material name="white"/>
    </visual>
    <collision>
      <origin rpy="0 0 0" xyz="0 0 0"/>
      <geometry>
        <mesh filename="file:////home/ponwalai/project_ws/install/lidar_description/share/lidar_description/meshes/wheel.STL"/>
      </geometry>
    </collision>
  </link>
  <link name="left_wheel_f">
    <inertial>
      <origin rpy="0 0 0" xyz="0 0 0"/>
      <mass value="5.5"/>
      <inertia ixx="0.018333333333333337" ixy="0.0" ixz="0.0" iyy="0.018333333333333337" iyz="0.0" izz="0.027500000000000004"/>
    </inertial>
    <visual>
      <origin rpy="0 0 0" xyz="0 0 0"/>
      <geometry>
        <mesh filename="file:////home/ponwalai/project_ws/install/lidar_description/share/lidar_description/meshes/wheel.STL"/>
      </geometry>
      <material name="white"/>
    </visual>
    <collision>
      <origin rpy="0 0 0" xyz="0 0 0"/>
      <geometry>
        <mesh filename="file:////home/ponwalai/project_ws/install/lidar_description/share/lidar_description/meshes/wheel.STL"/>
      </geometry>
    </collision>
  </link>
  <joint name="left_joint_b" type="continuous">
    <origin rpy="1.57079632679 0 0" xyz="-0.23216 0.78175 -0.205"/>
    <parent link="base_link"/>
    <child link="left_wheel_b"/>
    <axis xyz="0 0 1"/>
    <limit effort="10.0" lower="-3.14159265359" upper="3.14159265359" velocity="10.0"/>
  </joint>
  <joint name="right_joint_b" type="continuous">
    <origin rpy="-1.57079632679 0 0" xyz="-0.23216 -0.78175 -0.205"/>
    <parent link="base_link"/>
    <child link="right_wheel_b"/>
    <axis xyz="0 0 1"/>
    <limit effort="10.0" lower="-3.14159265359" upper="3.14159265359" velocity="10.0"/>
  </joint>
  <joint name="left_joint_f" type="continuous">
    <origin rpy="1.57079632679 0 0" xyz="0.23216 0.78175 -0.205"/>
    <parent link="base_link"/>
    <child link="left_wheel_f"/>
    <axis xyz="0 0 1"/>
    <limit effort="10.0" lower="-3.14159265359" upper="3.14159265359" velocity="10.0"/>
  </joint>
  <joint name="right_joint_f" type="continuous">
    <origin rpy="-1.57079632679 0 0" xyz="0.23216 -0.78175 -0.205"/>
    <parent link="base_link"/>
    <child link="right_wheel_f"/>
    <axis xyz="0 0 1"/>
    <limit effort="10.0" lower="-3.14159265359" upper="3.14159265359" velocity="10.0"/>
  </joint>
</robot>
