<?xml version="1.0"?>
<robot xmlns:xacro="http://www.ros.org/wiki/xacro" name="robot">

    <xacro:include filename="gazebo2.xacro"/>

    <material name="white">
        <color rgba="1 1 1 1"/>
    </material>

    <link name="dummy"/>

    <joint type="fixed" name="dummy">
        <parent link="dummy"/>
        <child link="base_link"/>
        <origin xyz="0 0 0.305" rpy="0 0 0" />
    </joint>

    <link name="base_link">
        <inertial>
            <!-- Mass -->
            <mass value="48.94155" />

            <!-- Center of Mass -->
            <origin xyz="-0.06061 0.03849 0.13055" />

            <!-- Inertia Matrix -->
            <inertia
            ixx="11.69721231776"
            ixy="-0.24793148078"
            ixz="0.13519725788"
            iyy="2.68655479586"
            iyz="-0.43545579979"
            izz="13.00728941730" />
        </inertial>
        <visual>
            <origin xyz="0 0 0" rpy="0 0 0" />
            <geometry>
                <mesh
                filename="file:///$(find lidar_description)/meshes/base_link.STL"/>
            </geometry>
            <material name="white"/>
        </visual>
        <collision>
            <origin xyz="0 0 0" rpy="0 0 0" />
            <geometry>
                <mesh
                filename="file:///$(find lidar_description)/meshes/base_link.STL"/>
            </geometry>
        </collision>
    </link>

    <link name="right_wheel_b">
        <xacro:inertial_cylinder mass="9.304" length="0.1" radius="0.1">
            <origin xyz="0 0 0" rpy="0 0 0"/>
        </xacro:inertial_cylinder>
        <visual>
            <origin xyz="0 0 0" rpy="0 0 0" />
            <geometry>
                <mesh
                filename="file:///$(find lidar_description)/meshes/wheel.STL" />
            </geometry>
            <material name="white"/>
        </visual>
        <collision>
            <origin xyz="0 0 0" rpy="0 0 0" />
            <geometry>
                <mesh
                filename="file:///$(find lidar_description)/meshes/wheel.STL" />
            </geometry>
        </collision>
    </link>

    <link name="left_wheel_b">
        <xacro:inertial_cylinder mass="9.304" length="0.1" radius="0.1">
            <origin xyz="0 0 0" rpy="0 0 0"/>
        </xacro:inertial_cylinder>
        <visual>
            <origin xyz="0 0 0" rpy="0 0 0" />
            <geometry>
                <mesh
                filename="file:///$(find lidar_description)/meshes/wheel.STL" />
            </geometry>
            <material name="white"/>
        </visual>
        <collision>
            <origin xyz="0 0 0" rpy="0 0 0" />
            <geometry>
                <mesh
                filename="file:///$(find lidar_description)/meshes/wheel.STL" />
            </geometry>
        </collision>
    </link>

    <link name="right_wheel_f">
        <xacro:inertial_cylinder mass="9.304" length="0.1" radius="0.1">
            <origin xyz="0 0 0" rpy="0 0 0"/>
        </xacro:inertial_cylinder>
        <visual>
            <origin xyz="0 0 0" rpy="0 0 0" />
            <geometry>
                <mesh
                filename="file:///$(find lidar_description)/meshes/wheel.STL" />
            </geometry>
            <material name="white"/>
        </visual>
        <collision>
            <origin xyz="0 0 0" rpy="0 0 0" />
            <geometry>
                <mesh
                filename="file:///$(find lidar_description)/meshes/wheel.STL" />
            </geometry>
        </collision>
    </link>

    <link name="left_wheel_f">
        <xacro:inertial_cylinder mass="9.304" length="0.1" radius="0.1">
            <origin xyz="0 0 0" rpy="0 0 0"/>
        </xacro:inertial_cylinder>
        <visual>
            <origin xyz="0 0 0" rpy="0 0 0" />
            <geometry>
                <mesh
                filename="file:///$(find lidar_description)/meshes/wheel.STL" />
            </geometry>
            <material name="white"/>
        </visual>
        <collision>
            <origin xyz="0 0 0" rpy="0 0 0" />
            <geometry>
                <mesh
                filename="file:///$(find lidar_description)/meshes/wheel.STL" />
            </geometry>
        </collision>
    </link>

    <joint name="left_joint_b" type="continuous">
        <origin xyz="-0.23216 0.78175 -0.205" rpy="1.57079632679 0 0" />
        <parent link="base_link" />
        <child link="left_wheel_b" />
        <axis xyz="0 0 1" />
        <limit 
            effort="10.0" 
            lower="-3.14159265359" 
            upper="3.14159265359" 
            velocity="10.0"
            />
    </joint>

    <joint name="right_joint_b" type="continuous">
        <origin xyz="-0.23216 -0.78175 -0.205" rpy="-1.57079632679 0 0" />
        <parent link="base_link" />
        <child link="right_wheel_b" />
        <axis xyz="0 0 1" />
        <limit 
            effort="10.0" 
            lower="-3.14159265359" 
            upper="3.14159265359" 
            velocity="10.0"
            />
    </joint>

    <joint name="left_joint_f" type="continuous">
        <origin xyz="0.23216 0.78175 -0.205" rpy="1.57079632679 0 0" />
        <parent link="base_link" />
        <child link="left_wheel_f" />
        <axis xyz="0 0 1" />
        <limit 
            effort="10.0" 
            lower="-3.14159265359" 
            upper="3.14159265359" 
            velocity="10.0"
            />
    </joint>

    <joint name="right_joint_f" type="continuous">
        <origin xyz="0.23216 -0.78175 -0.205" rpy="-1.57079632679 0 0" />
        <parent link="base_link" />
        <child link="right_wheel_f" />
        <axis xyz="0 0 1" />
        <limit 
            effort="10.0" 
            lower="-3.14159265359" 
            upper="3.14159265359" 
            velocity="10.0"
            />
    </joint>

</robot>
