<?xml version="1.0" ?>
<robot name="two_wheel_robot">
  <!-- Base Link -->
  <link name="base"/>

  <joint name="base_joint" type="fixed">
    <parent link="base"/>
    <child link="base_link"/>
    <origin xyz="0 0 0.2" rpy="0 0 0"/>
  </joint>

  <link name="base_link">
    <inertial>
      <origin xyz="0 0 0" rpy="0 0 0"/>
      <mass value="1.0"/>
      <inertia ixx="0.01666666666" ixy="0" ixz="0" 
              iyy="0.01416666666" iyz="0" 
              izz="0.00416666666"/>
    </inertial>
    <visual>
      <origin xyz="0 0 0" rpy="0 0 0"/>
      <geometry>
        <box size="0.1 0.2 0.4"/>
      </geometry>
      <material name="green">
        <color rgba="0 1 0 1"/>
      </material>
    </visual>
    <collision>
      <origin xyz="0 0 0" rpy="0 0 0"/>
      <geometry>
        <box size="0.1 0.2 0.4"/>
      </geometry>
    </collision>
  </link>

  <!-- Left Wheel -->
  <link name="left_wheel">
    <inertial>
      <origin xyz="0 0 0" rpy="0 0 0"/>
      <mass value="0.2"/>
      <inertia ixx="0.00013166666" ixy="0" ixz="0" 
              iyy="0.00013166666" iyz="0" izz="0.00025"/>
    </inertial>
    <visual>
      <geometry>
        <cylinder radius="0.05" length="0.02"/>
      </geometry>
      <material name="blue">
        <color rgba="0 0 1 1"/>
      </material>
    </visual>
    <collision>
      <geometry>
        <cylinder radius="0.05" length="0.02"/>
      </geometry>
    </collision>
  </link>

  <!-- Right Wheel -->
  <link name="right_wheel">
    <inertial>
      <origin xyz="0 0 0" rpy="0 0 0"/>
      <mass value="0.2"/>
      <inertia ixx="0.00013166666" ixy="0" ixz="0" 
              iyy="0.00013166666" iyz="0" izz="0.00025"/>
    </inertial>
    <visual>
      <geometry>
        <cylinder radius="0.05" length="0.02"/>
      </geometry>
      <material name="blue">
        <color rgba="0 0 1 1"/>
      </material>
    </visual>
    <collision>
      <geometry>
        <cylinder radius="0.05" length="0.02"/>
      </geometry>
    </collision>
  </link>

  <!-- Left Joint -->
  <joint name="left_joint" type="continuous">
    <parent link="base_link"/>
    <child link="left_wheel"/>
    <origin xyz="0 0.1 -0.2" rpy="1.57079632679 0 0"/>
    <axis xyz="0 0 1"/>
  </joint>

  <!-- Right Joint -->
  <joint name="right_joint" type="continuous">
    <parent link="base_link"/>
    <child link="right_wheel"/>
    <origin xyz="0 -0.1 -0.2" rpy="1.57079632679 0 0"/>
    <axis xyz="0 0 1"/>
  </joint>
</robot>
